<?xml version="1.0"?>
<robot name="mico" xmlns:xacro="http://www.ros.org/wiki/xacro"> 

 	<xacro:property name="j1_mechanical_reduction" value="1.0"/>
	<xacro:property name="j1_motor_torque_constant" value="50.0"/>
	<xacro:property name="j2_mechanical_reduction" value="1.0"/>
	<xacro:property name="j2_motor_torque_constant" value="50.0"/>
	<xacro:property name="j3_mechanical_reduction" value="1.0"/>
	<xacro:property name="j3_motor_torque_constant" value="50.0"/>
	<xacro:property name="j4_mechanical_reduction" value="1.0"/>
	<xacro:property name="j4_motor_torque_constant" value="5.0"/>
	<xacro:property name="j5_mechanical_reduction" value="1.0"/>
	<xacro:property name="j5_motor_torque_constant" value="5.0"/>
	<xacro:property name="j6_mechanical_reduction" value="1.0"/>
	<xacro:property name="j6_motor_torque_constant" value="5.0"/>
	<xacro:property name="jf1_mechanical_reduction" value="1.0"/>
	<xacro:property name="jf1_motor_torque_constant" value="5.0"/>
	<xacro:property name="jf2_mechanical_reduction" value="1.0"/>
	<xacro:property name="jf2_motor_torque_constant" value="5.0"/>
	<xacro:property name="jf3_mechanical_reduction" value="1.0"/>
	<xacro:property name="jf3_motor_torque_constant" value="5.0"/>

	
	<xacro:property name="j1_lower_limit" value="-3.13"/> 
	<xacro:property name="j1_upper_limit" value="3.13"/> 
	<xacro:property name="j2_lower_limit" value="-3.13"/> 
	<xacro:property name="j2_upper_limit" value="0.0"/> 
    <xacro:property name="j3_lower_limit" value="${-5*PI/4}"/> 
	<xacro:property name="j3_upper_limit" value="${PI/4}"/> 
	<xacro:property name="j4_lower_limit" value="-3.13"/> 
	<xacro:property name="j4_upper_limit" value="3.13"/> 
	<xacro:property name="j5_lower_limit" value="-3.13"/> 
	<xacro:property name="j5_upper_limit" value="3.13"/> 	
	<xacro:property name="j6_lower_limit" value="-1.52"/> 
	<xacro:property name="j6_upper_limit" value="4.70"/> 	
	<xacro:property name="jf1_lower_limit" value="0"/> 
	<xacro:property name="jf1_upper_limit" value="${PI/180*40}"/> 
	<xacro:property name="jf2_lower_limit" value="0"/> 
	<xacro:property name="jf2_upper_limit" value="${PI/180*40}"/> 
	<xacro:property name="jf3_lower_limit" value="0"/> 
	<xacro:property name="jf3_upper_limit" value="${PI/180*40}"/> 


	<xacro:property name="joint_effort_limit" value="60.0"/>
	<xacro:property name="joint_velocity_limit" value="2.9217"/>	
	<xacro:property name="joint_damping" value="0.7"/>
	<xacro:property name="joint_friction" value="0.5"/>

    <!-- xacro:property name="joint_finger_1" value="jaco2_joint_finger_1" / -->
    <xacro:property name="joint_finger_1_axis_xyz" value="0 0 1" />
    <xacro:property name="joint_finger_1_origin_xyz" value="-0.03978 0 -0.10071" />
    <xacro:property name="joint_finger_1_origin_rpy" value="-1.7983 1.117 3.1416" />
    <xacro:property name="joint_finger_1_lower_limit" value="0" />
    <xacro:property name="joint_finger_1_upper_limit" value="${PI/180*40}" />

    <!-- xacro:property name="joint_finger_2" value="jaco2_joint_finger_2" / -->
    <xacro:property name="joint_finger_2_axis_xyz" value="0 0 1" />
    <xacro:property name="joint_finger_2_origin_xyz" value="0.03569 -0.0216 -0.10071" />
    <xacro:property name="joint_finger_2_origin_rpy" value="-1.6222 1.117 -0.23615" />
    <xacro:property name="joint_finger_2_lower_limit" value="0" />
    <xacro:property name="joint_finger_2_upper_limit" value="${PI/180*40}" />

    <!-- xacro:property name="joint_finger_3" value="jaco2_joint_finger_3" / -->
    <xacro:property name="joint_finger_3_axis_xyz" value="0 0 1" />
    <xacro:property name="joint_finger_3_origin_xyz" value="0.03569 0.0216 -0.10071" />
    <xacro:property name="joint_finger_3_origin_rpy" value="-1.5161 1.1459 0.23978" />
    <xacro:property name="joint_finger_3_lower_limit" value="0" />
    <xacro:property name="joint_finger_3_upper_limit" value="${PI/180*40}" />

  <!-- 
  <property name="link_end_effector"   value="mico_end_effector" />
  <property name="end_effector_offset" value="0.160" / -->

	<xacro:macro name="mico" params="name hq">
		
    <!-- Robot mechanical and motor parameters -->
    <xacro:property name="PI" value="3.1415926535897931"/>

    					
	<!-- base_link -->
	<link name="mico_link_base">
		<inertial>
		  <mass value="0.506" />
		  <origin xyz="-0.05161 0 -0.003" />
		  <inertia  ixx="0.0014526484" ixy="0.0"  ixz="-8.792613e-005" iyy="0.0018217854" iyx="0.0"  iyz="0.0" izz="0.0008987159" />
		</inertial>
		<visual>
		   <origin xyz="0 0 0" rpy="0 0 0" />
		   <xacro:if value="${hq}">
		   <geometry>
			 <mesh filename="package://mico_description/meshes/arms/mico_link_base.dae"/>			 
		   </geometry>		   
		   </xacro:if>
		   <xacro:unless value="${hq}">
		   <geometry>
			  <mesh filename="package://mico_description/meshes/arms/mico_link_base.dae"/>			 
		   </geometry>
		   </xacro:unless>
		   <material name="carbon_fiber">
              <color rgba="0.792156862745098 0.819607843137255 0.933333333333333 1" />
           </material>		   
		</visual>  
		<collision>
		   <origin xyz="0 0 0" rpy="0 0 0 " />
		   <geometry>
			 <mesh filename="package://mico_description/meshes/arms/mico_link_base.dae"/>			 
		   </geometry>
		</collision>
	</link>
   
    <!-- LINK 1 -->
    <link name="mico_link_1">
		<inertial>
		  <mass value="0.7" />
		  <origin xyz="0.07155 0.00229 -0.00028" />
		  <inertia  ixx="0.0018430902" ixy="0.0001075379"  ixz="2.683183e-005"  iyy="0.0023530852"  iyz="4.5192e-007"  izz="0.0016327528" />
		</inertial>
		<visual>
		   <origin xyz="0 0 0" rpy="0 0 0" />
		   <xacro:if value="${hq}">
		   <geometry>
			 <mesh filename="package://mico_description/meshes/arms/mico_link_1.dae"/>			 
		   </geometry>
		   </xacro:if>
		   <xacro:unless value="${hq}">
		   <geometry>
		     <mesh filename="package://mico_description/meshes/arms/mico_link_1.dae"/>			 
		   </geometry>
		   </xacro:unless>
		   <material name="carbon_fiber">
              <color rgba="0.792156862745098 0.819607843137255 0.933333333333333 1" />
           </material>		   
		</visual>  
		<collision>
		   <origin xyz="0 0 0" rpy="0 0 0 " />
		   <geometry>
			 <mesh filename="package://mico_description/meshes/arms/mico_link_1.dae"/>				 	
		   </geometry>
		</collision>
	</link>

	<joint
		name="mico_joint_1"
		type="revolute">
		<origin
			xyz="0 0 0.1535"
			rpy="${PI} 0.0 ${PI}" />
		<parent link="mico_link_base" />	
		<child link="mico_link_1" />
		<axis xyz="0 0 -1" />
		<limit effort="${joint_effort_limit}" velocity="${joint_velocity_limit}" upper="${j1_upper_limit}" lower="${j1_lower_limit}"/>
		<dynamics damping="${joint_damping}" friction="${joint_friction}"/>
	</joint>
    
    <transmission name="j1_trans">
	 <type>transmission_interface/SimpleTransmission</type>
     <joint name="mico_joint_1">
        <hardwareInterface>EffortJointInterface</hardwareInterface>
     </joint>     
     <actuator name="j1_motor">
	    <hardwareInterface>EffortJointInterface</hardwareInterface>
        <mechanicalReduction>${j1_mechanical_reduction}</mechanicalReduction>
		<motorTorqueConstant>${j1_motor_torque_constant}</motorTorqueConstant>
	 </actuator>	 
    </transmission>
    
    <!-- LINK 2 -->
	<link name="mico_link_2">
		<inertial>
		  <mass value="0.429" />
		  <origin xyz="0.06076 0 -0.00014" />
		  <inertia  ixx="0.0011551458" ixy="-6.3e-010"  ixz="2.519546e-005"  iyy="0.0015754353"  iyz="-7.6e-010"  izz="0.0007798411" />
		</inertial>
		<visual>
		   <origin xyz="0 0 0" rpy="0 0 0" />
		   <xacro:if value="${hq}">
		   <geometry>
			 <mesh filename="package://mico_description/meshes/arms/mico_link_2.dae"/>				 	
		   </geometry>
		   </xacro:if>
		   <xacro:unless value="${hq}">
		   <geometry>
			 <mesh filename="package://mico_description/meshes/arms/mico_link_2.dae"/>				 	
		   </geometry>
		   </xacro:unless>
		   <material name="carbon_fiber">
              <color rgba="0.792156862745098 0.819607843137255 0.933333333333333 1" />
           </material>		   
		</visual>  
		<collision>
		   <origin xyz="0 0 0" rpy="0 0 0 " />
		   <geometry>
			 <mesh filename="package://mico_description/meshes/arms/mico_link_2.dae"/>				 	
		   </geometry>		   
		</collision>
	</link>

	<joint
		name="mico_joint_2"
		type="revolute">
	  <origin
        xyz="0 0 -0.1185"
        rpy="-${PI/2} ${PI} 0.0" />
	  <parent link="mico_link_1" />	
      <child link="mico_link_2" />
      <axis xyz="0 0 1" />
      <limit effort="${joint_effort_limit}" velocity="${joint_velocity_limit}" upper="${j2_upper_limit}" lower="${j2_lower_limit}"/>
      <dynamics damping="${joint_damping}" friction="${joint_friction}"/>
    </joint>
    
    <transmission name="j2_trans">
	 <type>transmission_interface/SimpleTransmission</type>
     <joint name="mico_joint_2">
        <hardwareInterface>EffortJointInterface</hardwareInterface>
     </joint>     
     <actuator name="j2_motor">
	    <hardwareInterface>EffortJointInterface</hardwareInterface>
        <mechanicalReduction>${j2_mechanical_reduction}</mechanicalReduction>
		<motorTorqueConstant>${j2_motor_torque_constant}</motorTorqueConstant>
	 </actuator>	 
    </transmission>
    
    <!-- LINK 3 -->
	<link name="mico_link_3">
		<inertial>
		  <mass value="0.351" />
		  <origin xyz="-0.07306 0 -0.00466" />
		  <inertia  ixx="0.0003749308" ixy="0.0"  ixz="-0.0001258961"  iyy="0.0010047174"  iyz="0.0"  izz="0.0009318091" />			
		</inertial>
		<visual>
		   <origin xyz="0 0 0" rpy="0 0 0" />
		   <xacro:if value="${hq}">
		   <geometry>
			 <mesh filename="package://mico_description/meshes/arms/mico_link_3.dae"/>			 
		   </geometry>
		   </xacro:if>
		   <xacro:unless value="${hq}">
		   <geometry>
		     <mesh filename="package://mico_description/meshes/arms/mico_link_3.dae"/>			 
		   </geometry>
		   </xacro:unless>
		   <material name="carbon_fiber">
              <color rgba="0.792156862745098 0.819607843137255 0.933333333333333 1" />
           </material>		   
		</visual>  
		<collision>
		   <origin xyz="0 0 0" rpy="0 0 0 " />
		   <geometry>
		     <mesh filename="package://mico_description/meshes/arms/mico_link_3.dae"/>			 
		   </geometry>
		</collision>
	</link>

	<joint
		name="mico_joint_3"
		type="revolute">
	  <origin
        xyz="0.29 0 0"
        rpy="${PI} 0.0 ${PI/2}" />
	  <parent link="mico_link_2" />	
      <child link="mico_link_3" />
      <axis xyz="0 0 -1" />
      <limit effort="${joint_effort_limit}" velocity="${joint_velocity_limit}" upper="${j3_upper_limit}" lower="${j3_lower_limit}"/>
      <dynamics damping="${joint_damping}" friction="${joint_friction}"/>
    </joint>
    
    <transmission name="j3_trans">
	 <type>transmission_interface/SimpleTransmission</type>
     <joint name="mico_joint_3">
        <hardwareInterface>EffortJointInterface</hardwareInterface>
     </joint>     		 
     <actuator name="j3_motor">
	    <hardwareInterface>EffortJointInterface</hardwareInterface>
        <mechanicalReduction>${j3_mechanical_reduction}</mechanicalReduction>
		<motorTorqueConstant>${j3_motor_torque_constant}</motorTorqueConstant>
	 </actuator>	 
    </transmission>


    <!-- LINK 4 -->
	<link name="mico_link_4">
		<inertial>
		  <mass value="0.429" />
		  <origin xyz="0.06076 0 -0.00014" />
		  <inertia  ixx="0.0011551458" ixy="-6.3e-010"  ixz="2.519546e-005"  iyy="0.0015754353"  iyz="-7.6e-010"  izz="0.0007798411" />
		</inertial>		
		<visual>
		   <origin xyz="0 0 0" rpy="0 0 0" />
		   <xacro:if value="${hq}">
		   <geometry>
			 <mesh filename="package://mico_description/meshes/arms/mico_link_4.dae"/>			 
		   </geometry>
		   </xacro:if>
		   <xacro:unless value="${hq}">
		   <geometry>
		     <mesh filename="package://mico_description/meshes/arms/mico_link_4.dae"/>			 
		   </geometry>
		   </xacro:unless>
		   <material name="carbon_fiber">
              <color rgba="0.792156862745098 0.819607843137255 0.933333333333333 1" />
           </material>		   
		</visual>  
		<collision>
		   <origin xyz="0 0 0" rpy="0 0 0 " />
		   <geometry>
		     <mesh filename="package://mico_description/meshes/arms/mico_link_4.dae"/>			 
		   </geometry>
		</collision>
	</link>

	<joint
		name="mico_joint_4"
		type="revolute">
	  <origin
        xyz="0.123 0 -0.00845"
        rpy="${PI} ${PI/2} 0.0" />
	  <parent link="mico_link_3" />	
      <child link="mico_link_4" />
      <axis xyz="0 0 -1" />
      <limit effort="${joint_effort_limit}" velocity="${joint_velocity_limit}" upper="${j4_upper_limit}" lower="${j4_lower_limit}"/>
      <dynamics damping="${joint_damping}" friction="${joint_friction}"/>
    </joint>
    
    <transmission name="j4_trans">
	 <type>transmission_interface/SimpleTransmission</type>
     <joint name="mico_joint_4">
        <hardwareInterface>EffortJointInterface</hardwareInterface>
     </joint>          
     <actuator name="j4_motor">
	    <hardwareInterface>EffortJointInterface</hardwareInterface>
        <mechanicalReduction>${j4_mechanical_reduction}</mechanicalReduction>
		<motorTorqueConstant>${j4_motor_torque_constant}</motorTorqueConstant>
	 </actuator>	 
    </transmission>


    <!-- LINK 5 -->
	<link name="mico_link_5">
		<inertial>
		  <mass value="0.429" />
		  <origin xyz="0.06076 0 -0.00014" />
		  <inertia  ixx="0.0011551458" ixy="-6.3e-010"  ixz="2.519546e-005"  iyy="0.0015754353"  iyz="-7.6e-010"  izz="0.0007798411" />
		</inertial>
		<visual>
		   <origin xyz="0 0 0" rpy="0 0 0" />
		   <xacro:if value="${hq}">
		   <geometry>
			 <mesh filename="package://mico_description/meshes/arms/mico_link_5.dae"/>			 
		   </geometry>
		   </xacro:if>
		   <xacro:unless value="${hq}">
		   <geometry>
		     <mesh filename="package://mico_description/meshes/arms/mico_link_5.dae"/>			 
		   </geometry>
		   </xacro:unless>
		   <material name="carbon_fiber">
              <color rgba="0.792156862745098 0.819607843137255 0.933333333333333 1" />
           </material>		   
		</visual>  
		<collision>
		   <origin xyz="0 0 0" rpy="0 0 0 " />
		   <geometry>
		     <mesh filename="package://mico_description/meshes/arms/mico_link_5.dae"/>			 
		   </geometry>
		</collision>
	</link>

	<joint
		name="mico_joint_5"
		type="revolute">
	  <origin
        xyz="0.037 0 -0.06408"
        rpy="0 -${PI/180*60} 0.0" />
	  <parent link="mico_link_4" />	
      <child link="mico_link_5" />
      <axis xyz="0 0 -1" />      
      <limit effort="${joint_effort_limit}" velocity="${joint_velocity_limit}" upper="${j5_upper_limit}" lower="${j5_lower_limit}"/>
      <dynamics damping="${joint_damping}" friction="${joint_friction}"/>
    </joint>
    
    <transmission name="j5_trans">
	 <type>transmission_interface/SimpleTransmission</type>
     <joint name="mico_joint_5">
        <hardwareInterface>EffortJointInterface</hardwareInterface>
     </joint>     		 
     <actuator name="j5_motor">
	    <hardwareInterface>EffortJointInterface</hardwareInterface>
        <mechanicalReduction>${j5_mechanical_reduction}</mechanicalReduction>
		<motorTorqueConstant>${j5_motor_torque_constant}</motorTorqueConstant>
	 </actuator>	 
    </transmission>

    <!-- LINK 6 -->
	<link name="mico_link_hand">
		<inertial>
		  <mass value="0.429" />
		  <origin xyz="0.06076 0 -0.00014" />
		  <inertia  ixx="0.0011551458" ixy="-6.3e-010"  ixz="2.519546e-005"  iyy="0.0015754353"  iyz="-7.6e-010"  izz="0.0007798411" />
		</inertial>
		<visual>
		   <origin xyz="0 0 0" rpy="0 0 0" />
		   <xacro:if value="${hq}">
		   <geometry>
			 <mesh filename="package://mico_description/meshes/arms/jaco2_link_hand.dae"/>			 
		   </geometry>
		   </xacro:if>
		   <xacro:unless value="${hq}">
		   <geometry>
		     <mesh filename="package://mico_description/meshes/arms/mico_link_hand.dae"/>			 
		   </geometry>
		   </xacro:unless>
		   <material name="carbon_fiber">
              <color rgba="0.792156862745098 0.819607843137255 0.933333333333333 1" />
           </material>		   
		</visual>  
		<collision>
		   <origin xyz="0 0 0" rpy="0 0 0 " />
		   <geometry>
		     <mesh filename="package://mico_description/meshes/arms/jaco2_link_hand.dae"/>			 
		   </geometry>
		</collision>
	</link>

	<joint
		name="mico_joint_6"
		type="revolute">
	  <origin
        xyz="0.037 0 -0.06408"
        rpy="-${PI/180*60} 0.0 ${PI/2}" />
	  <parent link="mico_link_5" />	
      <child link="mico_link_hand" />
      <axis xyz="0 0 -1" />
      <limit effort="${joint_effort_limit}" velocity="${joint_velocity_limit}" upper="${j6_upper_limit}" lower="${j6_lower_limit}"/>
      <dynamics damping="${joint_damping}" friction="${joint_friction}"/>
    </joint>
    
    <transmission name="j6_trans">
	 <type>transmission_interface/SimpleTransmission</type>
     <joint name="mico_joint_6">
        <hardwareInterface>EffortJointInterface</hardwareInterface>
     </joint>     
     <actuator name="j6_motor">
	    <hardwareInterface>EffortJointInterface</hardwareInterface>
        <mechanicalReduction>${j6_mechanical_reduction}</mechanicalReduction>
		<motorTorqueConstant>${j6_motor_torque_constant}</motorTorqueConstant>
	 </actuator>	 
    </transmission>

    <!-- LINK FINGER 1 -->
	<link name="mico_link_finger_1">
		<inertial>
		  <mass value="0.050" />
		  <origin xyz="0.03 0.03 0.03" />
		  <inertia  ixx="0.0011551458" ixy="-6.3e-010"  ixz="2.519546e-005"  iyy="0.0015754353"  iyz="-7.6e-010"  izz="0.0007798411" />
		</inertial>
		<visual>
		   <origin xyz="0 0 0" rpy="0 0 0" />
		   <xacro:if value="${hq}">
		   <geometry>
			 <mesh filename="package://mico_description/meshes/arms/mico_link_finger_1.dae"/>			 
		   </geometry>
		   </xacro:if>
		   <xacro:unless value="${hq}">
		   <geometry>
		     <mesh filename="package://mico_description/meshes/arms/mico_link_finger_1.dae"/>			 
		   </geometry>
		   </xacro:unless>
		   <material name="carbon_fiber">
              <color rgba="0.792156862745098 0.819607843137255 0.933333333333333 1" />
           </material>		   
		</visual>  
		<collision>
		   <origin xyz="0 0 0" rpy="0 0 0 " />
		   <geometry>
		     <mesh filename="package://mico_description/meshes/arms/mico_link_finger_1.dae"/>			 
		   </geometry>
		</collision>
	</link>

	<joint
		name="mico_joint_finger_1"
		type="revolute">
	  <origin
        xyz="${joint_finger_1_origin_xyz}"
        rpy="${joint_finger_1_origin_rpy}"/>
	  <parent link="mico_link_hand" />	
      <child link="mico_link_finger_1" />
      <axis xyz="${joint_finger_1_axis_xyz}" />
      <limit effort="${joint_effort_limit}" velocity="${joint_velocity_limit}" upper="${joint_finger_1_upper_limit}" lower="${joint_finger_1_lower_limit}"/>
      <dynamics damping="${joint_damping}" friction="${joint_friction}"/>
    </joint>
        
    <transmission name="jf1_trans">
	 <type>transmission_interface/SimpleTransmission</type>
     <joint name="mico_joint_finger_1">
        <hardwareInterface>EffortJointInterface</hardwareInterface>
     </joint>     		 
     <actuator name="jf1_motor">
	    <hardwareInterface>EffortJointInterface</hardwareInterface>
        <mechanicalReduction>${jf1_mechanical_reduction}</mechanicalReduction>
		<motorTorqueConstant>${jf1_motor_torque_constant}</motorTorqueConstant>
	 </actuator>	 
    </transmission>



    <!-- LINK FINGER 2 -->
	<link name="mico_link_finger_2">
		<inertial>
		  <mass value="0.050" />
		  <origin xyz="0.03 0.03 0.03" />
		  <inertia  ixx="0.0011551458" ixy="-6.3e-010"  ixz="2.519546e-005"  iyy="0.0015754353"  iyz="-7.6e-010"  izz="0.0007798411" />
		</inertial>
		<visual>
		   <origin xyz="0 0 0" rpy="0 0 0" />
		   <xacro:if value="${hq}">
		   <geometry>
			 <mesh filename="package://mico_description/meshes/arms/mico_link_finger_2.dae"/>			 
		   </geometry>
		   </xacro:if>
		   <xacro:unless value="${hq}">
		   <geometry>
		     <mesh filename="package://mico_description/meshes/arms/mico_link_finger_2.dae"/>			 
		   </geometry>
		   </xacro:unless>
		   <material name="carbon_fiber">
              <color rgba="0.792156862745098 0.819607843137255 0.933333333333333 1" />
           </material>		   
		</visual>  
		<collision>
		   <origin xyz="0 0 0" rpy="0 0 0 " />
		   <geometry>
		     <mesh filename="package://mico_description/meshes/arms/mico_link_finger_2.dae"/>			 
		   </geometry>
		</collision>
	</link>

	<joint
		name="mico_joint_finger_2"
		type="revolute">
	  <origin
        xyz="${joint_finger_2_origin_xyz}"
        rpy="${joint_finger_2_origin_rpy}" />
	  <parent link="mico_link_hand" />	
      <child link="mico_link_finger_2" />
      <axis xyz="${joint_finger_2_axis_xyz}" />
      <limit effort="${joint_effort_limit}" velocity="${joint_velocity_limit}" upper="${joint_finger_2_upper_limit}" lower="${joint_finger_2_lower_limit}"/>
      <dynamics damping="${joint_damping}" friction="${joint_friction}"/>
    </joint>
        
    <transmission name="jf2_trans">
	 <type>transmission_interface/SimpleTransmission</type>
     <joint name="mico_joint_finger_2">
        <hardwareInterface>EffortJointInterface</hardwareInterface>
     </joint>     
     <actuator name="jf2_motor">
	    <hardwareInterface>EffortJointInterface</hardwareInterface>
        <mechanicalReduction>${jf2_mechanical_reduction}</mechanicalReduction>
		<motorTorqueConstant>${jf2_motor_torque_constant}</motorTorqueConstant>
	 </actuator>	 
    </transmission>



    <!-- LINK FINGER 3 -->
	<link name="mico_link_finger_3">
		<inertial>
		  <mass value="0.050" />
		  <origin xyz="0.03 0.03 0.03" />
		  <inertia  ixx="0.0011551458" ixy="-6.3e-010"  ixz="2.519546e-005"  iyy="0.0015754353"  iyz="-7.6e-010"  izz="0.0007798411" />
		</inertial>
		<visual>
		   <origin xyz="0 0 0" rpy="0 0 0" />
		   <xacro:if value="${hq}">
		   <geometry>
			 <mesh filename="package://mico_description/meshes/arms/mico_link_finger_3.dae"/>			 
		   </geometry>
		   </xacro:if>
		   <xacro:unless value="${hq}">
		   <geometry>
		     <mesh filename="package://mico_description/meshes/arms/mico_link_finger_3.dae"/>			 
		   </geometry>
		   </xacro:unless>
		   <material name="carbon_fiber">
              <color rgba="0.792156862745098 0.819607843137255 0.933333333333333 1" />
           </material>		   
		</visual>  
		<collision>
		   <origin xyz="0 0 0" rpy="0 0 0 " />
		   <geometry>
		     <mesh filename="package://mico_description/meshes/arms/mico_link_finger_3.dae"/>			 
		   </geometry>
		</collision>
	</link>

	<joint
		name="mico_joint_finger_3"
		type="revolute">
	  <origin
        xyz="${joint_finger_3_origin_xyz}"
        rpy="${joint_finger_3_origin_rpy}" />
	  <parent link="mico_link_hand" />	
      <child link="mico_link_finger_3" />
      <axis xyz="${joint_finger_3_axis_xyz}" />
      <limit effort="${joint_effort_limit}" velocity="${joint_velocity_limit}" upper="${joint_finger_3_upper_limit}" lower="${joint_finger_3_lower_limit}"/>
      <dynamics damping="${joint_damping}" friction="${joint_friction}"/>
    </joint>
        
    <transmission name="jf3_trans">
	 <type>transmission_interface/SimpleTransmission</type>
     <joint name="mico_joint_finger_3">
        <hardwareInterface>EffortJointInterface</hardwareInterface>
     </joint>     
     <actuator name="jf3_motor">
	    <hardwareInterface>EffortJointInterface</hardwareInterface>
        <mechanicalReduction>${jf3_mechanical_reduction}</mechanicalReduction>
		<motorTorqueConstant>${jf3_motor_torque_constant}</motorTorqueConstant>
	 </actuator>	 
    </transmission>

  </xacro:macro>
</robot>


